Watching for file changes with StatReloader
System check identified some issues:

WARNINGS:
todos.Todo: (models.W042) Auto-created primary key used when not defining a primary key type, by default 'django.db.models.AutoField'.
	HINT: Configure the DEFAULT_AUTO_FIELD setting or the TodosConfig.default_auto_field attribute to point to a subclass of AutoField, e.g. 'django.db.models.BigAutoField'.

System check identified 1 issue (0 silenced).
[16/Mar/2024 00:41:22] "GET /todos/ HTTP/1.1" 200 3515
[16/Mar/2024 00:41:22] "GET /static/css/style.css HTTP/1.1" 304 0
Performing system checks...

March 16, 2024 - 00:35:07
Django version 5.0.3, using settings 'todoApp.settings'
Starting development server at http://0.0.0.0:8000/
Quit the server with CONTROL-C.

Watching for file changes with StatReloader
System check identified some issues:

WARNINGS:
todos.Todo: (models.W042) Auto-created primary key used when not defining a primary key type, by default 'django.db.models.AutoField'.
	HINT: Configure the DEFAULT_AUTO_FIELD setting or the TodosConfig.default_auto_field attribute to point to a subclass of AutoField, e.g. 'django.db.models.BigAutoField'.

System check identified 1 issue (0 silenced).
Error: That port is already in use.
Watching for file changes with StatReloader
System check identified some issues:

WARNINGS:
todos.Todo: (models.W042) Auto-created primary key used when not defining a primary key type, by default 'django.db.models.AutoField'.
	HINT: Configure the DEFAULT_AUTO_FIELD setting or the TodosConfig.default_auto_field attribute to point to a subclass of AutoField, e.g. 'django.db.models.BigAutoField'.

System check identified 1 issue (0 silenced).
Error: That port is already in use.
Watching for file changes with StatReloader
System check identified some issues:

WARNINGS:
todos.Todo: (models.W042) Auto-created primary key used when not defining a primary key type, by default 'django.db.models.AutoField'.
	HINT: Configure the DEFAULT_AUTO_FIELD setting or the TodosConfig.default_auto_field attribute to point to a subclass of AutoField, e.g. 'django.db.models.BigAutoField'.

System check identified 1 issue (0 silenced).
[16/Mar/2024 00:53:42] "GET /todos/ HTTP/1.1" 200 3515
[16/Mar/2024 00:53:48] "GET /todos/ HTTP/1.1" 200 3515
[16/Mar/2024 01:00:23] "POST /todos/add/ HTTP/1.1" 302 0
[16/Mar/2024 01:00:23] "GET /todos/ HTTP/1.1" 200 4089
[16/Mar/2024 01:00:23] "GET /static/css/style.css HTTP/1.1" 304 0
[16/Mar/2024 02:58:01] "GET / HTTP/1.0" 302 0
[16/Mar/2024 03:44:20] "GET / HTTP/1.1" 302 0
[16/Mar/2024 03:44:21] code 400, message Bad request syntax ('\x16\x03\x01\x00î\x01\x00\x00ê\x03\x03¦´Q\x97%îuÃ\x99\x19Þyw')
[16/Mar/2024 03:44:21] You're accessing the development server over HTTPS, but it only supports HTTP.
[16/Mar/2024 03:44:21] code 400, message Bad HTTP/0.9 request type ('t3')
[16/Mar/2024 03:44:21] "t3 12.1.2" 400 -
[16/Mar/2024 03:45:01] "GET / HTTP/1.1" 302 0
Not Found: /favicon.ico
[16/Mar/2024 03:45:01] "GET /favicon.ico HTTP/1.1" 404 2574
Not Found: /todos/robots.txt
[16/Mar/2024 03:45:02] "GET /todos/robots.txt HTTP/1.1" 404 3207
Not Found: /todos/sitemap.xml
[16/Mar/2024 03:45:02] "GET /todos/sitemap.xml HTTP/1.1" 404 3210
[16/Mar/2024 03:45:03] "GET /todos HTTP/1.1" 301 0
Not Found: /favicon.ico
[16/Mar/2024 03:45:03] "GET /favicon.ico HTTP/1.1" 404 2574
Not Found: /todos/sitemap.xml
[16/Mar/2024 03:45:03] "GET /todos/sitemap.xml HTTP/1.1" 404 3210
Not Found: /todos/robots.txt
[16/Mar/2024 03:45:03] "GET /todos/robots.txt HTTP/1.1" 404 3207
[16/Mar/2024 03:45:05] "GET /todos/ HTTP/1.1" 200 4089
Not Found: /favicon.ico
[16/Mar/2024 03:45:05] "GET /favicon.ico HTTP/1.1" 404 2574
Not Found: /todos/sitemap.xml
Not Found: /todos/robots.txt
[16/Mar/2024 03:45:06] "GET /todos/sitemap.xml HTTP/1.1" 404 3210
[16/Mar/2024 03:45:06] "GET /todos/robots.txt HTTP/1.1" 404 3207
[16/Mar/2024 10:58:04] code 400, message Bad request version ('À\x14À')
[16/Mar/2024 10:58:04] You're accessing the development server over HTTPS, but it only supports HTTP.
[16/Mar/2024 11:08:25,471] - Broken pipe from ('104.152.52.203', 45669)
[16/Mar/2024 11:21:19] "GET / HTTP/1.1" 302 0
Internal Server Error: /todos/
Traceback (most recent call last):
  File "/home/ubuntu/.local/lib/python3.10/site-packages/django/db/backends/base/base.py", line 275, in ensure_connection
    self.connect()
  File "/home/ubuntu/.local/lib/python3.10/site-packages/django/utils/asyncio.py", line 26, in inner
    return func(*args, **kwargs)
  File "/home/ubuntu/.local/lib/python3.10/site-packages/django/db/backends/base/base.py", line 256, in connect
    self.connection = self.get_new_connection(conn_params)
  File "/home/ubuntu/.local/lib/python3.10/site-packages/django/utils/asyncio.py", line 26, in inner
    return func(*args, **kwargs)
  File "/home/ubuntu/.local/lib/python3.10/site-packages/django/db/backends/sqlite3/base.py", line 181, in get_new_connection
    conn = Database.connect(**conn_params)
sqlite3.OperationalError: unable to open database file

The above exception was the direct cause of the following exception:

Traceback (most recent call last):
  File "/home/ubuntu/.local/lib/python3.10/site-packages/django/core/handlers/exception.py", line 55, in inner
    response = get_response(request)
  File "/home/ubuntu/.local/lib/python3.10/site-packages/django/core/handlers/base.py", line 220, in _get_response
    response = response.render()
  File "/home/ubuntu/.local/lib/python3.10/site-packages/django/template/response.py", line 114, in render
    self.content = self.rendered_content
  File "/home/ubuntu/.local/lib/python3.10/site-packages/django/template/response.py", line 92, in rendered_content
    return template.render(context, self._request)
  File "/home/ubuntu/.local/lib/python3.10/site-packages/django/template/backends/django.py", line 61, in render
    return self.template.render(context)
  File "/home/ubuntu/.local/lib/python3.10/site-packages/django/template/base.py", line 171, in render
    return self._render(context)
  File "/home/ubuntu/.local/lib/python3.10/site-packages/django/template/base.py", line 163, in _render
    return self.nodelist.render(context)
  File "/home/ubuntu/.local/lib/python3.10/site-packages/django/template/base.py", line 1000, in render
    return SafeString("".join([node.render_annotated(context) for node in self]))
  File "/home/ubuntu/.local/lib/python3.10/site-packages/django/template/base.py", line 1000, in <listcomp>
    return SafeString("".join([node.render_annotated(context) for node in self]))
  File "/home/ubuntu/.local/lib/python3.10/site-packages/django/template/base.py", line 961, in render_annotated
    return self.render(context)
  File "/home/ubuntu/.local/lib/python3.10/site-packages/django/template/loader_tags.py", line 159, in render
    return compiled_parent._render(context)
  File "/home/ubuntu/.local/lib/python3.10/site-packages/django/template/base.py", line 163, in _render
    return self.nodelist.render(context)
  File "/home/ubuntu/.local/lib/python3.10/site-packages/django/template/base.py", line 1000, in render
    return SafeString("".join([node.render_annotated(context) for node in self]))
  File "/home/ubuntu/.local/lib/python3.10/site-packages/django/template/base.py", line 1000, in <listcomp>
    return SafeString("".join([node.render_annotated(context) for node in self]))
  File "/home/ubuntu/.local/lib/python3.10/site-packages/django/template/base.py", line 961, in render_annotated
    return self.render(context)
  File "/home/ubuntu/.local/lib/python3.10/site-packages/django/template/loader_tags.py", line 65, in render
    result = block.nodelist.render(context)
  File "/home/ubuntu/.local/lib/python3.10/site-packages/django/template/base.py", line 1000, in render
    return SafeString("".join([node.render_annotated(context) for node in self]))
  File "/home/ubuntu/.local/lib/python3.10/site-packages/django/template/base.py", line 1000, in <listcomp>
    return SafeString("".join([node.render_annotated(context) for node in self]))
  File "/home/ubuntu/.local/lib/python3.10/site-packages/django/template/base.py", line 961, in render_annotated
    return self.render(context)
  File "/home/ubuntu/.local/lib/python3.10/site-packages/django/template/defaulttags.py", line 198, in render
    len_values = len(values)
  File "/home/ubuntu/.local/lib/python3.10/site-packages/django/db/models/query.py", line 382, in __len__
    self._fetch_all()
  File "/home/ubuntu/.local/lib/python3.10/site-packages/django/db/models/query.py", line 1928, in _fetch_all
    self._result_cache = list(self._iterable_class(self))
  File "/home/ubuntu/.local/lib/python3.10/site-packages/django/db/models/query.py", line 91, in __iter__
    results = compiler.execute_sql(
  File "/home/ubuntu/.local/lib/python3.10/site-packages/django/db/models/sql/compiler.py", line 1560, in execute_sql
    cursor = self.connection.cursor()
  File "/home/ubuntu/.local/lib/python3.10/site-packages/django/utils/asyncio.py", line 26, in inner
    return func(*args, **kwargs)
  File "/home/ubuntu/.local/lib/python3.10/site-packages/django/db/backends/base/base.py", line 316, in cursor
    return self._cursor()
  File "/home/ubuntu/.local/lib/python3.10/site-packages/django/db/backends/base/base.py", line 292, in _cursor
    self.ensure_connection()
  File "/home/ubuntu/.local/lib/python3.10/site-packages/django/utils/asyncio.py", line 26, in inner
    return func(*args, **kwargs)
  File "/home/ubuntu/.local/lib/python3.10/site-packages/django/db/backends/base/base.py", line 274, in ensure_connection
    with self.wrap_database_errors:
  File "/home/ubuntu/.local/lib/python3.10/site-packages/django/db/utils.py", line 91, in __exit__
    raise dj_exc_value.with_traceback(traceback) from exc_value
  File "/home/ubuntu/.local/lib/python3.10/site-packages/django/db/backends/base/base.py", line 275, in ensure_connection
    self.connect()
  File "/home/ubuntu/.local/lib/python3.10/site-packages/django/utils/asyncio.py", line 26, in inner
    return func(*args, **kwargs)
  File "/home/ubuntu/.local/lib/python3.10/site-packages/django/db/backends/base/base.py", line 256, in connect
    self.connection = self.get_new_connection(conn_params)
  File "/home/ubuntu/.local/lib/python3.10/site-packages/django/utils/asyncio.py", line 26, in inner
    return func(*args, **kwargs)
  File "/home/ubuntu/.local/lib/python3.10/site-packages/django/db/backends/sqlite3/base.py", line 181, in get_new_connection
    conn = Database.connect(**conn_params)
django.db.utils.OperationalError: unable to open database file
[16/Mar/2024 11:21:20] "GET /todos/ HTTP/1.1" 500 218834
Not Found: /favicon.ico
[16/Mar/2024 11:21:21] "GET /favicon.ico HTTP/1.1" 404 2574
[16/Mar/2024 11:26:16] "GET / HTTP/1.1" 302 0
Internal Server Error: /todos/
Traceback (most recent call last):
  File "/home/ubuntu/.local/lib/python3.10/site-packages/django/db/backends/base/base.py", line 275, in ensure_connection
    self.connect()
  File "/home/ubuntu/.local/lib/python3.10/site-packages/django/utils/asyncio.py", line 26, in inner
    return func(*args, **kwargs)
  File "/home/ubuntu/.local/lib/python3.10/site-packages/django/db/backends/base/base.py", line 256, in connect
    self.connection = self.get_new_connection(conn_params)
  File "/home/ubuntu/.local/lib/python3.10/site-packages/django/utils/asyncio.py", line 26, in inner
    return func(*args, **kwargs)
  File "/home/ubuntu/.local/lib/python3.10/site-packages/django/db/backends/sqlite3/base.py", line 181, in get_new_connection
    conn = Database.connect(**conn_params)
sqlite3.OperationalError: unable to open database file

The above exception was the direct cause of the following exception:

Traceback (most recent call last):
  File "/home/ubuntu/.local/lib/python3.10/site-packages/django/core/handlers/exception.py", line 55, in inner
    response = get_response(request)
  File "/home/ubuntu/.local/lib/python3.10/site-packages/django/core/handlers/base.py", line 220, in _get_response
    response = response.render()
  File "/home/ubuntu/.local/lib/python3.10/site-packages/django/template/response.py", line 114, in render
    self.content = self.rendered_content
  File "/home/ubuntu/.local/lib/python3.10/site-packages/django/template/response.py", line 92, in rendered_content
    return template.render(context, self._request)
  File "/home/ubuntu/.local/lib/python3.10/site-packages/django/template/backends/django.py", line 61, in render
    return self.template.render(context)
  File "/home/ubuntu/.local/lib/python3.10/site-packages/django/template/base.py", line 171, in render
    return self._render(context)
  File "/home/ubuntu/.local/lib/python3.10/site-packages/django/template/base.py", line 163, in _render
    return self.nodelist.render(context)
  File "/home/ubuntu/.local/lib/python3.10/site-packages/django/template/base.py", line 1000, in render
    return SafeString("".join([node.render_annotated(context) for node in self]))
  File "/home/ubuntu/.local/lib/python3.10/site-packages/django/template/base.py", line 1000, in <listcomp>
    return SafeString("".join([node.render_annotated(context) for node in self]))
  File "/home/ubuntu/.local/lib/python3.10/site-packages/django/template/base.py", line 961, in render_annotated
    return self.render(context)
  File "/home/ubuntu/.local/lib/python3.10/site-packages/django/template/loader_tags.py", line 159, in render
    return compiled_parent._render(context)
  File "/home/ubuntu/.local/lib/python3.10/site-packages/django/template/base.py", line 163, in _render
    return self.nodelist.render(context)
  File "/home/ubuntu/.local/lib/python3.10/site-packages/django/template/base.py", line 1000, in render
    return SafeString("".join([node.render_annotated(context) for node in self]))
  File "/home/ubuntu/.local/lib/python3.10/site-packages/django/template/base.py", line 1000, in <listcomp>
    return SafeString("".join([node.render_annotated(context) for node in self]))
  File "/home/ubuntu/.local/lib/python3.10/site-packages/django/template/base.py", line 961, in render_annotated
    return self.render(context)
  File "/home/ubuntu/.local/lib/python3.10/site-packages/django/template/loader_tags.py", line 65, in render
    result = block.nodelist.render(context)
  File "/home/ubuntu/.local/lib/python3.10/site-packages/django/template/base.py", line 1000, in render
    return SafeString("".join([node.render_annotated(context) for node in self]))
  File "/home/ubuntu/.local/lib/python3.10/site-packages/django/template/base.py", line 1000, in <listcomp>
    return SafeString("".join([node.render_annotated(context) for node in self]))
  File "/home/ubuntu/.local/lib/python3.10/site-packages/django/template/base.py", line 961, in render_annotated
    return self.render(context)
  File "/home/ubuntu/.local/lib/python3.10/site-packages/django/template/defaulttags.py", line 198, in render
    len_values = len(values)
  File "/home/ubuntu/.local/lib/python3.10/site-packages/django/db/models/query.py", line 382, in __len__
    self._fetch_all()
  File "/home/ubuntu/.local/lib/python3.10/site-packages/django/db/models/query.py", line 1928, in _fetch_all
    self._result_cache = list(self._iterable_class(self))
  File "/home/ubuntu/.local/lib/python3.10/site-packages/django/db/models/query.py", line 91, in __iter__
    results = compiler.execute_sql(
  File "/home/ubuntu/.local/lib/python3.10/site-packages/django/db/models/sql/compiler.py", line 1560, in execute_sql
    cursor = self.connection.cursor()
  File "/home/ubuntu/.local/lib/python3.10/site-packages/django/utils/asyncio.py", line 26, in inner
    return func(*args, **kwargs)
  File "/home/ubuntu/.local/lib/python3.10/site-packages/django/db/backends/base/base.py", line 316, in cursor
    return self._cursor()
  File "/home/ubuntu/.local/lib/python3.10/site-packages/django/db/backends/base/base.py", line 292, in _cursor
    self.ensure_connection()
  File "/home/ubuntu/.local/lib/python3.10/site-packages/django/utils/asyncio.py", line 26, in inner
    return func(*args, **kwargs)
  File "/home/ubuntu/.local/lib/python3.10/site-packages/django/db/backends/base/base.py", line 274, in ensure_connection
    with self.wrap_database_errors:
  File "/home/ubuntu/.local/lib/python3.10/site-packages/django/db/utils.py", line 91, in __exit__
    raise dj_exc_value.with_traceback(traceback) from exc_value
  File "/home/ubuntu/.local/lib/python3.10/site-packages/django/db/backends/base/base.py", line 275, in ensure_connection
    self.connect()
  File "/home/ubuntu/.local/lib/python3.10/site-packages/django/utils/asyncio.py", line 26, in inner
    return func(*args, **kwargs)
  File "/home/ubuntu/.local/lib/python3.10/site-packages/django/db/backends/base/base.py", line 256, in connect
    self.connection = self.get_new_connection(conn_params)
  File "/home/ubuntu/.local/lib/python3.10/site-packages/django/utils/asyncio.py", line 26, in inner
    return func(*args, **kwargs)
  File "/home/ubuntu/.local/lib/python3.10/site-packages/django/db/backends/sqlite3/base.py", line 181, in get_new_connection
    conn = Database.connect(**conn_params)
django.db.utils.OperationalError: unable to open database file
[16/Mar/2024 11:26:17] "GET /todos/ HTTP/1.1" 500 218989
Performing system checks...

March 16, 2024 - 00:53:37
Django version 5.0.3, using settings 'todoApp.settings'
Starting development server at http://0.0.0.0:8000/
Quit the server with CONTROL-C.

